Invalid HTTP_HOST header: '54.173.7.151'. You may need to add '54.173.7.151' to ALLOWED_HOSTS.
Invalid HTTP_HOST header: '54.173.7.151'. You may need to add '54.173.7.151' to ALLOWED_HOSTS.
Invalid HTTP_HOST header: 'briansclub.cm'. You may need to add 'briansclub.cm' to ALLOWED_HOSTS.
Invalid HTTP_HOST header: '169.254.169.254'. You may need to add '169.254.169.254' to ALLOWED_HOSTS.
Invalid HTTP_HOST header: 'forum.exploit.in'. You may need to add 'forum.exploit.in' to ALLOWED_HOSTS.
Invalid HTTP_HOST header: '127.0.0.1:8000'. You may need to add '127.0.0.1' to ALLOWED_HOSTS.
Invalid HTTP_HOST header: 'briansclub.cm'. You may need to add 'briansclub.cm' to ALLOWED_HOSTS.
testingInternal Server Error: /
Traceback (most recent call last):
  File "/home/chris/.local/lib/python3.10/site-packages/django/db/backends/utils.py", line 89, in _execute
    return self.cursor.execute(sql, params)
  File "/home/chris/.local/lib/python3.10/site-packages/django/db/backends/sqlite3/base.py", line 357, in execute
    return Database.Cursor.execute(self, query, params)
sqlite3.OperationalError: no such table: trackapp_acc_positions

The above exception was the direct cause of the following exception:

Traceback (most recent call last):
  File "/home/chris/.local/lib/python3.10/site-packages/django/core/handlers/exception.py", line 55, in inner
    response = get_response(request)
  File "/home/chris/.local/lib/python3.10/site-packages/django/core/handlers/base.py", line 197, in _get_response
    response = wrapped_callback(request, *callback_args, **callback_kwargs)
  File "/home/chris/TheFounders/trackapp/views.py", line 11, in index
    total_all_positions = Acc_Positions.objects.count()
  File "/home/chris/.local/lib/python3.10/site-packages/django/db/models/manager.py", line 85, in manager_method
    return getattr(self.get_queryset(), name)(*args, **kwargs)
  File "/home/chris/.local/lib/python3.10/site-packages/django/db/models/query.py", line 621, in count
    return self.query.get_count(using=self.db)
  File "/home/chris/.local/lib/python3.10/site-packages/django/db/models/sql/query.py", line 559, in get_count
    return obj.get_aggregation(using, ["__count"])["__count"]
  File "/home/chris/.local/lib/python3.10/site-packages/django/db/models/sql/query.py", line 544, in get_aggregation
    result = compiler.execute_sql(SINGLE)
  File "/home/chris/.local/lib/python3.10/site-packages/django/db/models/sql/compiler.py", line 1398, in execute_sql
    cursor.execute(sql, params)
  File "/home/chris/.local/lib/python3.10/site-packages/django/db/backends/utils.py", line 103, in execute
    return super().execute(sql, params)
  File "/home/chris/.local/lib/python3.10/site-packages/django/db/backends/utils.py", line 67, in execute
    return self._execute_with_wrappers(
  File "/home/chris/.local/lib/python3.10/site-packages/django/db/backends/utils.py", line 80, in _execute_with_wrappers
    return executor(sql, params, many, context)
  File "/home/chris/.local/lib/python3.10/site-packages/django/db/backends/utils.py", line 84, in _execute
    with self.db.wrap_database_errors:
  File "/home/chris/.local/lib/python3.10/site-packages/django/db/utils.py", line 91, in __exit__
    raise dj_exc_value.with_traceback(traceback) from exc_value
  File "/home/chris/.local/lib/python3.10/site-packages/django/db/backends/utils.py", line 89, in _execute
    return self.cursor.execute(sql, params)
  File "/home/chris/.local/lib/python3.10/site-packages/django/db/backends/sqlite3/base.py", line 357, in execute
    return Database.Cursor.execute(self, query, params)
django.db.utils.OperationalError: no such table: trackapp_acc_positions
"GET / HTTP/1.1" 500 129455
